{
 "cells": [
  {
   "cell_type": "code",
   "execution_count": null,
   "metadata": {},
   "outputs": [
    {
     "ename": "",
     "evalue": "",
     "output_type": "error",
     "traceback": [
      "\u001b[1;31mFailed to start the Kernel. \n",
      "Traceback (most recent call last):\n",
      "  File \"/home/quantium/.vscode/extensions/ms-toolsai.jupyter-2022.4.1021342353/pythonFiles/vscode_datascience_helpers/jupyter_daemon.py\", line 158, in _start_notebook\n",
      "    from notebook import notebookapp as app\n",
      "  File \"/home/quantium/.local/lib/python3.8/site-packages/notebook/notebookapp.py\", line 43, in <module>\n",
      "    from jinja2 import Environment, FileSystemLoader\n",
      "  File \"/usr/lib/python3/dist-packages/jinja2/__init__.py\", line 33, in <module>\n",
      "    from jinja2.environment import Environment, Template\n",
      "  File \"/usr/lib/python3/dist-packages/jinja2/environment.py\", line 15, in <module>\n",
      "    from jinja2 import nodes\n",
      "  File \"/usr/lib/python3/dist-packages/jinja2/nodes.py\", line 23, in <module>\n",
      "    from jinja2.utils import Markup\n",
      "  File \"/usr/lib/python3/dist-packages/jinja2/utils.py\", line 656, in <module>\n",
      "    from markupsafe import Markup, escape, soft_unicode\n",
      "ImportError: cannot import name 'soft_unicode' from 'markupsafe' (/home/quantium/.local/lib/python3.8/site-packages/markupsafe/__init__.py)\n",
      "\n",
      "During handling of the above exception, another exception occurred:\n",
      "\n",
      "Traceback (most recent call last):\n",
      "  File \"/home/quantium/.vscode/extensions/ms-toolsai.jupyter-2022.4.1021342353/pythonFiles/vscode_datascience_helpers/daemon/daemon_python.py\", line 54, in _decorator\n",
      "    return func(self, *args, **kwargs)\n",
      "  File \"/home/quantium/.vscode/extensions/ms-toolsai.jupyter-2022.4.1021342353/pythonFiles/vscode_datascience_helpers/jupyter_daemon.py\", line 111, in m_exec_module_observable\n",
      "    self._start_notebook(args, cwd, env)\n",
      "  File \"/home/quantium/.vscode/extensions/ms-toolsai.jupyter-2022.4.1021342353/pythonFiles/vscode_datascience_helpers/jupyter_daemon.py\", line 160, in _start_notebook\n",
      "    from notebook import app as app\n",
      "ImportError: cannot import name 'app' from 'notebook' (/home/quantium/.local/lib/python3.8/site-packages/notebook/__init__.py)\n",
      "\n",
      "Failed to run jupyter as observable with args notebook --no-browser --notebook-dir=\"/home/quantium/labs/fx-oanda\" --config=/tmp/5f22e08a-fa17-4945-a8f6-5a8b2e051f66/jupyter_notebook_config.py --NotebookApp.iopub_data_rate_limit=10000000000.0. \n",
      "View Jupyter <a href='command:jupyter.viewOutput'>log</a> for further details."
     ]
    }
   ],
   "source": [
    "import pandas as pd\n",
    "import matplotlib as mpl\n",
    "import matplotlib.pyplot as plt\n"
   ]
  },
  {
   "cell_type": "code",
   "execution_count": null,
   "metadata": {},
   "outputs": [
    {
     "ename": "",
     "evalue": "",
     "output_type": "error",
     "traceback": [
      "\u001b[1;31mFailed to start the Kernel. \n",
      "Traceback (most recent call last):\n",
      "  File \"/home/quantium/.vscode/extensions/ms-toolsai.jupyter-2022.4.1021342353/pythonFiles/vscode_datascience_helpers/jupyter_daemon.py\", line 158, in _start_notebook\n",
      "    from notebook import notebookapp as app\n",
      "  File \"/home/quantium/.local/lib/python3.8/site-packages/notebook/notebookapp.py\", line 43, in <module>\n",
      "    from jinja2 import Environment, FileSystemLoader\n",
      "  File \"/usr/lib/python3/dist-packages/jinja2/__init__.py\", line 33, in <module>\n",
      "    from jinja2.environment import Environment, Template\n",
      "  File \"/usr/lib/python3/dist-packages/jinja2/environment.py\", line 15, in <module>\n",
      "    from jinja2 import nodes\n",
      "  File \"/usr/lib/python3/dist-packages/jinja2/nodes.py\", line 23, in <module>\n",
      "    from jinja2.utils import Markup\n",
      "  File \"/usr/lib/python3/dist-packages/jinja2/utils.py\", line 656, in <module>\n",
      "    from markupsafe import Markup, escape, soft_unicode\n",
      "ImportError: cannot import name 'soft_unicode' from 'markupsafe' (/home/quantium/.local/lib/python3.8/site-packages/markupsafe/__init__.py)\n",
      "\n",
      "During handling of the above exception, another exception occurred:\n",
      "\n",
      "Traceback (most recent call last):\n",
      "  File \"/home/quantium/.vscode/extensions/ms-toolsai.jupyter-2022.4.1021342353/pythonFiles/vscode_datascience_helpers/daemon/daemon_python.py\", line 54, in _decorator\n",
      "    return func(self, *args, **kwargs)\n",
      "  File \"/home/quantium/.vscode/extensions/ms-toolsai.jupyter-2022.4.1021342353/pythonFiles/vscode_datascience_helpers/jupyter_daemon.py\", line 111, in m_exec_module_observable\n",
      "    self._start_notebook(args, cwd, env)\n",
      "  File \"/home/quantium/.vscode/extensions/ms-toolsai.jupyter-2022.4.1021342353/pythonFiles/vscode_datascience_helpers/jupyter_daemon.py\", line 160, in _start_notebook\n",
      "    from notebook import app as app\n",
      "ImportError: cannot import name 'app' from 'notebook' (/home/quantium/.local/lib/python3.8/site-packages/notebook/__init__.py)\n",
      "\n",
      "Failed to run jupyter as observable with args notebook --no-browser --notebook-dir=\"/home/quantium/labs/fx-oanda\" --config=/tmp/a4d42bc5-f84f-42e0-bd9f-a1f9f5a7dee6/jupyter_notebook_config.py --NotebookApp.iopub_data_rate_limit=10000000000.0. \n",
      "View Jupyter <a href='command:jupyter.viewOutput'>log</a> for further details."
     ]
    }
   ],
   "source": []
  }
 ],
 "metadata": {
  "interpreter": {
   "hash": "916dbcbb3f70747c44a77c7bcd40155683ae19c65e1c03b4aa3499c5328201f1"
  },
  "kernelspec": {
   "display_name": "Python 3.8.10 64-bit",
   "language": "python",
   "name": "python3"
  },
  "language_info": {
   "name": "python",
   "version": "3.8.10"
  },
  "orig_nbformat": 4
 },
 "nbformat": 4,
 "nbformat_minor": 2
}
